<?xml version="1.0" ?>
<!-- =================================================================================== -->
<!-- |    This document was autogenerated by xacro from robotiq-3f-gripper_articulated.xacro      | -->
<!-- |    EDITING THIS FILE BY HAND IS NOT RECOMMENDED                                 | -->
<!-- =================================================================================== -->
<!-- 
robotiq-3f-gripper_articulated - articulated version of the robotiq robotiq-3f-gripper,
3 fingered gripper.                                                
-->
<robot name="robotiq-3f-gripper_articulated" xmlns:xacro="http://ros.org/wiki/xacro">
  <material name="green">
    <color rgba="0 1 0 1"/>
  </material>
  <material name="red">
    <color rgba="1 0 0 1"/>
  </material>
  <material name="yellow">
    <color rgba="1 1 0 1"/>
  </material>

  <link name="finger_A_link_0">
    <visual>
      <origin rpy="0 0 0" xyz="0.020 0 0"/>
      <geometry>
        <mesh filename="meshes/robotiq-3f-gripper_articulated/visual/link_0.dae"/>
      </geometry>
      <material name="green"/>
    </visual>
    <collision>
      <origin rpy="0 3.1416 -1.5708" xyz="-0.0455 0.0414 0.036"/>
      <geometry>
        <mesh filename="meshes/robotiq-3f-gripper_articulated/collision/link_0.STL"/>
      </geometry>
      <material name="yellow"/>
    </collision>
    <inertial>
      <origin rpy="0 0 0" xyz="0 0 0"/>
      <mass value="0.05"/>
      <inertia ixx="0.01" ixy="-0.00002" ixz="0.00001" iyy="0.0008" iyz="0" izz="0.001"/>
    </inertial>
  </link>
  <link name="finger_A_link_1">
    <visual>
      <origin rpy="0 0 -0.47124" xyz="0.050 -.028 0"/>
      <geometry>
        <mesh filename="meshes/robotiq-3f-gripper_articulated/visual/link_1.dae"/>
      </geometry>
      <material name="red"/>
    </visual>
    <collision>
      <origin rpy="0 0 -0.47124" xyz="0.050 -.028 0"/>
      <geometry>
        <mesh filename="meshes/robotiq-3f-gripper_articulated/collision/link_1.STL"/>
      </geometry>
      <material name="yellow"/>
    </collision>
    <inertial>
      <origin rpy="0 0 0" xyz="0 0 0"/>
      <mass value="0.15"/>
      <inertia ixx="0.001859" ixy="-0.000376" ixz="0.000028" iyy="0.012756" iyz="0" izz="0.0024"/>
    </inertial>
  </link>
  <link name="finger_A_link_2">
    <!--
			NOTE: This link has an offset in the z-direction based on the models that were
			used to generate grap-it poses.  With the offset below the model appears visually
			correct, but it is suspect.
			-->
    <visual>
      <origin rpy="0 0 0" xyz="0.039 0 0.0075"/>
      <geometry>
        <mesh filename="meshes/robotiq-3f-gripper_articulated/visual/link_2.dae"/>
      </geometry>
      <material name="green"/>
    </visual>
    <collision>
      <origin rpy="0 0 0" xyz="0.039 0 0.0075"/>
      <geometry>
        <mesh filename="meshes/robotiq-3f-gripper_articulated/collision/link_2.STL"/>
      </geometry>
      <material name="yellow"/>
    </collision>
    <inertial>
      <origin rpy="0 0 0" xyz="0 0 0"/>
      <mass value="0.15"/>
      <inertia ixx="0.001859" ixy="-0.000376" ixz="0.000028" iyy="0.012756" iyz="0" izz="0.0024"/>
    </inertial>
  </link>
  <link name="finger_A_link_3">
    <visual>
      <origin rpy="0 0 0.47124" xyz="0 0 0"/>
      <geometry>
        <mesh filename="meshes/robotiq-3f-gripper_articulated/visual/link_3.dae"/>
      </geometry>
      <material name="red"/>
    </visual>
    <collision>
      <origin rpy="0 0 0.47124" xyz="0 0 0"/>
      <geometry>
        <mesh filename="meshes/robotiq-3f-gripper_articulated/collision/link_3.STL"/>
      </geometry>
      <material name="yellow"/>
    </collision>
    <inertial>
      <origin rpy="0 0 0" xyz="0 0 0"/>
      <mass value="0.05"/>
      <inertia ixx="0.001239" ixy="-0.000251" ixz="0.000019" iyy="0.00085" iyz="0" izz="0.001632"/>
    </inertial>
  </link>
  <joint name="finger_A_joint_1" type="revolute">
    <parent link="finger_A_link_0"/>
    <child link="finger_A_link_1"/>
    <axis xyz="0 0 1"/>
    <origin rpy="0 0 0" xyz="0.020 0 0"/>
    <limit effort="100" lower="0" upper="1.2217" velocity="100"/> <!-- 0 to 70 deg -->
  </joint>
  <joint name="finger_A_joint_2" type="revolute">
    <parent link="finger_A_link_1"/>
    <child link="finger_A_link_2"/>
    <axis xyz="0 0 1"/>
    <origin rpy="0 0 -0.47124" xyz="0.050 -.028 0"/>
    <limit effort="100" lower="0" upper="1.5708" velocity="100"/> <!-- 0 to 90 deg -->
  </joint>
  <joint name="finger_A_joint_3" type="revolute">
    <parent link="finger_A_link_2"/>
    <child link="finger_A_link_3"/>
    <axis xyz="0 0 1"/>
    <origin rpy="0 0 0" xyz="0.039 0 0"/>
    <limit effort="100" lower="-0.90757" upper="0.80285" velocity="100"/> <!-- -52 to 46 deg -->
  </joint>
  <link name="palm">
    <visual>
      <geometry>
        <mesh filename="meshes/robotiq-3f-gripper_articulated/visual/palm.dae"/>
      </geometry>
      <material name="yellow"/>
    </visual>
    <collision>
      <geometry>
        <mesh filename="meshes/robotiq-3f-gripper_articulated/collision/palm.STL"/>
      </geometry>
      <material name="yellow"/>
    </collision>
    <inertial>
      <origin rpy="0 0 0" xyz="0 0 0"/>
      <mass value="1.3"/>
      <inertia ixx="0.006012" ixy="0.000079" ixz="-0.00024" iyy="0.012892" iyz="0" izz="0.002435"/>
    </inertial>
  </link>

  <link name="finger_B_link_0">
    <visual>
      <origin rpy="0 0 0" xyz="0.020 0 0"/>
      <geometry>
        <mesh filename="meshes/robotiq-3f-gripper_articulated/visual/link_0.dae"/>
      </geometry>
      <material name="green"/>
    </visual>
    <collision>
      <origin rpy="0 3.1416 -1.5708" xyz="-0.0455 0.0414 0.036"/>
      <geometry>
        <mesh filename="meshes/robotiq-3f-gripper_articulated/collision/link_0.STL"/>
      </geometry>
      <material name="yellow"/>
    </collision>
    <inertial>
      <origin rpy="0 0 0" xyz="0 0 0"/>
      <mass value="0.05"/>
      <inertia ixx="0.01" ixy="-0.00002" ixz="0.00001" iyy="0.0008" iyz="0" izz="0.001"/>
    </inertial>
  </link>
  <link name="finger_B_link_1">
    <visual>
      <origin rpy="0 0 -0.47124" xyz="0.050 -.028 0"/>
      <geometry>
        <mesh filename="meshes/robotiq-3f-gripper_articulated/visual/link_1.dae"/>
      </geometry>
      <material name="red"/>
    </visual>
    <collision>
      <origin rpy="0 0 -0.47124" xyz="0.050 -.028 0"/>
      <geometry>
        <mesh filename="meshes/robotiq-3f-gripper_articulated/collision/link_1.STL"/>
      </geometry>
      <material name="yellow"/>
    </collision>
    <inertial>
      <origin rpy="0 0 0" xyz="0 0 0"/>
      <mass value="0.15"/>
      <inertia ixx="0.001859" ixy="-0.000376" ixz="0.000028" iyy="0.012756" iyz="0" izz="0.0024"/>
    </inertial>
  </link>
  <link name="finger_B_link_2">
    <!--
			NOTE: This link has an offset in the z-direction based on the models that were
			used to generate grap-it poses.  With the offset below the model appears visually
			correct, but it is suspect.
			-->
    <visual>
      <origin rpy="0 0 0" xyz="0.039 0 0.0075"/>
      <geometry>
        <mesh filename="meshes/robotiq-3f-gripper_articulated/visual/link_2.dae"/>
      </geometry>
      <material name="green"/>
    </visual>
    <collision>
      <origin rpy="0 0 0" xyz="0.039 0 0.0075"/>
      <geometry>
        <mesh filename="meshes/robotiq-3f-gripper_articulated/collision/link_2.STL"/>
      </geometry>
      <material name="yellow"/>
    </collision>
    <inertial>
      <origin rpy="0 0 0" xyz="0 0 0"/>
      <mass value="0.15"/>
      <inertia ixx="0.001859" ixy="-0.000376" ixz="0.000028" iyy="0.012756" iyz="0" izz="0.0024"/>
    </inertial>
  </link>
  <link name="finger_B_link_3">
    <visual>
      <origin rpy="0 0 0.47124" xyz="0 0 0"/>
      <geometry>
        <mesh filename="meshes/robotiq-3f-gripper_articulated/visual/link_3.dae"/>
      </geometry>
      <material name="red"/>
    </visual>
    <collision>
      <origin rpy="0 0 0.47124" xyz="0 0 0"/>
      <geometry>
        <mesh filename="meshes/robotiq-3f-gripper_articulated/collision/link_3.STL"/>
      </geometry>
      <material name="yellow"/>
    </collision>
    <inertial>
      <origin rpy="0 0 0" xyz="0 0 0"/>
      <mass value="0.05"/>
      <inertia ixx="0.001239" ixy="-0.000251" ixz="0.000019" iyy="0.00085" iyz="0" izz="0.001632"/>
    </inertial>
  </link>
  <joint name="finger_B_joint_1" type="revolute">
    <parent link="finger_B_link_0"/>
    <child link="finger_B_link_1"/>
    <axis xyz="0 0 1"/>
    <origin rpy="0 0 0" xyz="0.020 0 0"/>
    <limit effort="100" lower="0" upper="1.2217" velocity="100"/> <!-- 0 to 70 deg -->
  </joint>
  <joint name="finger_B_joint_2" type="revolute">
    <parent link="finger_B_link_1"/>
    <child link="finger_B_link_2"/>
    <axis xyz="0 0 1"/>
    <origin rpy="0 0 -0.47124" xyz="0.050 -.028 0"/>
    <limit effort="100" lower="0" upper="1.5708" velocity="100"/> <!-- 0 to 90 deg -->
  </joint>
  <joint name="finger_B_joint_3" type="revolute">
    <parent link="finger_B_link_2"/>
    <child link="finger_B_link_3"/>
    <axis xyz="0 0 1"/>
    <origin rpy="0 0 0" xyz="0.039 0 0"/>
    <limit effort="100" lower="-0.90757" upper="0.80285" velocity="100"/> <!-- -52 to 46 deg -->
  </joint>
  
  <link name="finger_C_link_0">
    <visual>
      <origin rpy="0 0 0" xyz="0.020 0 0"/>
      <geometry>
        <mesh filename="meshes/robotiq-3f-gripper_articulated/visual/link_0.dae"/>
      </geometry>
      <material name="green"/>
    </visual>
    <collision>
      <origin rpy="0 3.1416 -1.5708" xyz="-0.0455 0.0414 0.036"/>
      <geometry>
        <mesh filename="meshes/robotiq-3f-gripper_articulated/collision/link_0.STL"/>
      </geometry>
      <material name="yellow"/>
    </collision>
    <inertial>
      <origin rpy="0 0 0" xyz="0 0 0"/>
      <mass value="0.05"/>
      <inertia ixx="0.01" ixy="-0.00002" ixz="0.00001" iyy="0.0008" iyz="0" izz="0.001"/>
    </inertial>
  </link>
  <link name="finger_C_link_1">
    <visual>
      <origin rpy="0 0 -0.47124" xyz="0.050 -.028 0"/>
      <geometry>
        <mesh filename="meshes/robotiq-3f-gripper_articulated/visual/link_1.dae"/>
      </geometry>
      <material name="red"/>
    </visual>
    <collision>
      <origin rpy="0 0 -0.47124" xyz="0.050 -.028 0"/>
      <geometry>
        <mesh filename="meshes/robotiq-3f-gripper_articulated/collision/link_1.STL"/>
      </geometry>
      <material name="yellow"/>
    </collision>
    <inertial>
      <origin rpy="0 0 0" xyz="0 0 0"/>
      <mass value="0.15"/>
      <inertia ixx="0.001859" ixy="-0.000376" ixz="0.000028" iyy="0.012756" iyz="0" izz="0.0024"/>
    </inertial>
  </link>
  <link name="finger_C_link_2">
    <!--
			NOTE: This link has an offset in the z-direction based on the models that were
			used to generate grap-it poses.  With the offset below the model appears visually
			correct, but it is suspect.
			-->
    <visual>
      <origin rpy="0 0 0" xyz="0.039 0 0.0075"/>
      <geometry>
        <mesh filename="meshes/robotiq-3f-gripper_articulated/visual/link_2.dae"/>
      </geometry>
      <material name="green"/>
    </visual>
    <collision>
      <origin rpy="0 0 0" xyz="0.039 0 0.0075"/>
      <geometry>
        <mesh filename="meshes/robotiq-3f-gripper_articulated/collision/link_2.STL"/>
      </geometry>
      <material name="yellow"/>
    </collision>
    <inertial>
      <origin rpy="0 0 0" xyz="0 0 0"/>
      <mass value="0.15"/>
      <inertia ixx="0.001859" ixy="-0.000376" ixz="0.000028" iyy="0.012756" iyz="0" izz="0.0024"/>
    </inertial>
  </link>
  <link name="finger_C_link_3">
    <visual>
      <origin rpy="0 0 0.47124" xyz="0 0 0"/>
      <geometry>
        <mesh filename="meshes/robotiq-3f-gripper_articulated/visual/link_3.dae"/>
      </geometry>
      <material name="red"/>
    </visual>
    <collision>
      <origin rpy="0 0 0.47124" xyz="0 0 0"/>
      <geometry>
        <mesh filename="meshes/robotiq-3f-gripper_articulated/collision/link_3.STL"/>
      </geometry>
      <material name="yellow"/>
    </collision>
    <inertial>
      <origin rpy="0 0 0" xyz="0 0 0"/>
      <mass value="0.05"/>
      <inertia ixx="0.001239" ixy="-0.000251" ixz="0.000019" iyy="0.00085" iyz="0" izz="0.001632"/>
    </inertial>
  </link>
  <joint name="finger_C_joint_1" type="revolute">
    <parent link="finger_C_link_0"/>
    <child link="finger_C_link_1"/>
    <axis xyz="0 0 1"/>
    <origin rpy="0 0 0" xyz="0.020 0 0"/>
    <limit effort="100" lower="0" upper="1.2217" velocity="100"/> <!-- 0 to 70 deg -->
  </joint>
  <joint name="finger_C_joint_2" type="revolute">
    <parent link="finger_C_link_1"/>
    <child link="finger_C_link_2"/>
    <axis xyz="0 0 1"/>
    <origin rpy="0 0 -0.47124" xyz="0.050 -.028 0"/>
    <limit effort="100" lower="0" upper="1.5708" velocity="100"/> <!-- 0 to 90 deg -->
  </joint>
  <joint name="finger_C_joint_3" type="revolute">
    <parent link="finger_C_link_2"/>
    <child link="finger_C_link_3"/>
    <axis xyz="0 0 1"/>
    <origin rpy="0 0 0" xyz="0.039 0 0"/>
    <limit effort="100" lower="-0.90757" upper="0.80285" velocity="100"/> <!-- -52 to 46 deg -->
  </joint>

  <joint name="palm_finger_A_joint" type="fixed">
    <parent link="palm"/>
    <child link="finger_A_link_0"/>
    <axis xyz="0 0 1"/>
    <origin rpy="0 0 1.5708" xyz="0.0455 0.0214 0"/>
  </joint>
  <joint name="palm_finger_B_joint" type="revolute">
    <parent link="palm"/>
    <child link="finger_B_link_0"/>
    <axis xyz="0 1 0"/>
    <origin rpy="0 3.1416 -1.5708" xyz="-0.0455 0.0214 -0.036"/>
    <limit effort="100" lower="-0.27925" upper="0.17453" velocity="100"/> <!-- -16 to 10 deg -->
  </joint>
  <joint name="palm_finger_C_joint" type="revolute">
    <parent link="palm"/>
    <child link="finger_C_link_0"/>
    <axis xyz="0 1 0"/>
    <origin rpy="0 3.1416 -1.5708" xyz="-0.0455 0.0214 0.036"/>
    <limit effort="100" lower="-0.17453" upper="0.27925" velocity="100"/> <!-- -10 to 16 deg -->
  </joint>
  <!--
        <include filename="$(find robotiq_3f_gripper_visualization)/cfg/robotiq-3f-gripper_finger_articulated_macro.xacro" />
        <xacro:robotiq-3f-gripper_finger_articulated prefix=""/>
-->
</robot>
