<?xml version="1.0" ?>
<!-- =================================================================================== -->
<!-- |    This document was autogenerated by xacro from urdf/ur10_robot.urdf.xacro     | -->
<!-- |    EDITING THIS FILE BY HAND IS NOT RECOMMENDED                                 | -->
<!-- =================================================================================== -->
<robot name="ur10" xmlns:xacro="http://www.ros.org/wiki/xacro">
  <material name="green">
    <color rgba="0 1 0 1"/>
  </material>
  <material name="red">
    <color rgba="1 0 0 1"/>
  </material>
  <material name="yellow">
    <color rgba="1 1 0 1"/>
  </material>
  <material name="transparent">
    <color rgba="1 1 1 0.5"/>
  </material>



  <!-- ur10 -->
  <!-- arm -->
  <link name="base_link">
    <visual>
      <geometry>
        <mesh filename="meshes/ur10/visual/Base.dae"/>
      </geometry>
    </visual>
    <collision>
      <geometry>
        <mesh filename="meshes/ur10/collision/Base.dae"/>
      </geometry>
    </collision>
    <inertial>
      <mass value="4.0"/>
      <origin rpy="0 0 0" xyz="0.0 0.0 0.0"/>
      <inertia ixx="0.0061063308908" ixy="0.0" ixz="0.0" iyy="0.0061063308908" iyz="0.0" izz="0.01125"/>
    </inertial>
  </link>
  <joint name="shoulder_pan_joint" type="revolute">
    <parent link="base_link"/>
    <child link="shoulder_link"/>
    <origin rpy="0.0 0.0 0.0" xyz="0.0 0.0 0.1273"/>
    <axis xyz="0 0 1"/>
    <limit effort="330.0" lower="-6.2831853" upper="6.2831853" velocity="2.16"/>
    <dynamics damping="0.0" friction="0.0"/>
  </joint>
  <link name="shoulder_link">
    <visual>
      <geometry>
        <mesh filename="meshes/ur10/visual/Shoulder.dae"/>
      </geometry>
    </visual>
    <collision>
      <geometry>
        <mesh filename="meshes/ur10/collision/Shoulder.dae"/>
      </geometry>
    </collision>
    <inertial>
      <mass value="7.778"/>
      <origin rpy="0 0 0" xyz="0.0 0.0 0.0"/>
      <inertia ixx="0.0314743125769" ixy="0.0" ixz="0.0" iyy="0.0314743125769" iyz="0.0" izz="0.021875625"/>
    </inertial>
  </link>
  <joint name="shoulder_lift_joint" type="revolute">
    <parent link="shoulder_link"/>
    <child link="upper_arm_link"/>
    <origin rpy="0.0 1.570796325 0.0" xyz="0.0 0.220941 0.0"/>
    <axis xyz="0 1 0"/>
    <limit effort="330.0" lower="-6.2831853" upper="6.2831853" velocity="2.16"/>
    <dynamics damping="0.0" friction="0.0"/>
  </joint>
  <link name="upper_arm_link">
    <visual>
      <geometry>
        <mesh filename="meshes/ur10/visual/UpperArm.dae"/>
      </geometry>
    </visual>
    <collision>
      <geometry>
        <mesh filename="meshes/ur10/collision/UpperArm.dae"/>
      </geometry>
    </collision>
    <inertial>
      <mass value="12.93"/>
      <origin rpy="0 0 0" xyz="0.0 0.0 0.306"/>
      <inertia ixx="0.421753803798" ixy="0.0" ixz="0.0" iyy="0.421753803798" iyz="0.0" izz="0.036365625"/>
    </inertial>
  </link>
  <joint name="elbow_joint" type="revolute">
    <parent link="upper_arm_link"/>
    <child link="forearm_link"/>
    <origin rpy="0.0 0.0 0.0" xyz="0.0 -0.1719 0.612"/>
    <axis xyz="0 1 0"/>
    <limit effort="150.0" lower="-6.2831853" upper="6.2831853" velocity="3.15"/>
    <dynamics damping="0.0" friction="0.0"/>
  </joint>
  <link name="forearm_link">
    <visual>
      <geometry>
        <mesh filename="meshes/ur10/visual/Forearm.dae"/>
      </geometry>
    </visual>
    <collision>
      <geometry>
        <mesh filename="meshes/ur10/collision/Forearm.dae"/>
      </geometry>
    </collision>
    <inertial>
      <mass value="3.87"/>
      <origin rpy="0 0 0" xyz="0.0 0.0 0.28615"/>
      <inertia ixx="0.111069694097" ixy="0.0" ixz="0.0" iyy="0.111069694097" iyz="0.0" izz="0.010884375"/>
    </inertial>
  </link>
  <joint name="wrist_1_joint" type="revolute">
    <parent link="forearm_link"/>
    <child link="wrist_1_link"/>
    <origin rpy="0.0 1.570796325 0.0" xyz="0.0 0.0 0.5723"/>
    <axis xyz="0 1 0"/>
    <limit effort="54.0" lower="-6.2831853" upper="6.2831853" velocity="3.2"/>
    <dynamics damping="0.0" friction="0.0"/>
  </joint>
  <link name="wrist_1_link">
    <visual>
      <geometry>
        <mesh filename="meshes/ur10/visual/Wrist1.dae"/>
      </geometry>
    </visual>
    <collision>
      <geometry>
        <mesh filename="meshes/ur10/collision/Wrist1.dae"/>
      </geometry>
    </collision>
    <inertial>
      <mass value="1.96"/>
      <origin rpy="0 0 0" xyz="0.0 0.0 0.0"/>
      <inertia ixx="0.0051082479567" ixy="0.0" ixz="0.0" iyy="0.0051082479567" iyz="0.0" izz="0.0055125"/>
    </inertial>
  </link>
  <joint name="wrist_2_joint" type="revolute">
    <parent link="wrist_1_link"/>
    <child link="wrist_2_link"/>
    <origin rpy="0.0 0.0 0.0" xyz="0.0 0.1149 0.0"/>
    <axis xyz="0 0 1"/>
    <limit effort="54.0" lower="-6.2831853" upper="6.2831853" velocity="3.2"/>
    <dynamics damping="0.0" friction="0.0"/>
  </joint>
  <link name="wrist_2_link">
    <visual>
      <geometry>
        <mesh filename="meshes/ur10/visual/Wrist2.dae"/>
      </geometry>
    </visual>
    <collision>
      <geometry>
        <mesh filename="meshes/ur10/collision/Wrist2.dae"/>
      </geometry>
    </collision>
    <inertial>
      <mass value="1.96"/>
      <origin rpy="0 0 0" xyz="0.0 0.0 0.0"/>
      <inertia ixx="0.0051082479567" ixy="0.0" ixz="0.0" iyy="0.0051082479567" iyz="0.0" izz="0.0055125"/>
    </inertial>
  </link>
  <joint name="wrist_3_joint" type="revolute">
    <parent link="wrist_2_link"/>
    <child link="wrist_3_link"/>
    <origin rpy="0.0 0.0 0.0" xyz="0.0 0.0 0.1157"/>
    <axis xyz="0 1 0"/>
    <limit effort="54.0" lower="-6.2831853" upper="6.2831853" velocity="3.2"/>
    <dynamics damping="0.0" friction="0.0"/>
  </joint>
  <link name="wrist_3_link">
    <visual>
      <geometry>
        <mesh filename="meshes/ur10/visual/Wrist3.dae"/>
      </geometry>
      <material name="red"/>
    </visual>
    <collision>
      <geometry>
        <mesh filename="meshes/ur10/collision/Wrist3.dae"/>
      </geometry>
    </collision>
    <inertial>
      <mass value="0.202"/>
      <origin rpy="0 0 0" xyz="0.0 0.0 0.0"/>
      <inertia ixx="0.000526462289415" ixy="0.0" ixz="0.0" iyy="0.000526462289415" iyz="0.0" izz="0.000568125"/>
    </inertial>
  </link>


  <link name="finger_A_link_0">
    <visual>
      <origin rpy="0 0 0" xyz="0.020 0 0"/>
      <geometry>
        <mesh filename="meshes/robotiq-3f-gripper_articulated/visual/link_0.dae"/>
      </geometry>
      <material name="green"/>
    </visual>
    <collision>
      <origin rpy="0 3.1416 -1.5708" xyz="-0.0455 0.0414 0.036"/>
      <geometry>
        <mesh filename="meshes/robotiq-3f-gripper_articulated/collision/link_0.STL"/>
      </geometry>
      <material name="yellow"/>
    </collision>
    <inertial>
      <origin rpy="0 0 0" xyz="0 0 0"/>
      <mass value="0.05"/>
      <inertia ixx="0.01" ixy="-0.00002" ixz="0.00001" iyy="0.0008" iyz="0" izz="0.001"/>
    </inertial>
  </link>
  <link name="finger_A_link_1">
    <visual>
      <origin rpy="0 0 -0.47124" xyz="0.050 -.028 0"/>
      <geometry>
        <mesh filename="meshes/robotiq-3f-gripper_articulated/visual/link_1.dae"/>
      </geometry>
      <material name="red"/>
    </visual>
    <collision>
      <origin rpy="0 0 -0.47124" xyz="0.050 -.028 0"/>
      <geometry>
        <mesh filename="meshes/robotiq-3f-gripper_articulated/collision/link_1.STL"/>
      </geometry>
      <material name="yellow"/>
    </collision>
    <inertial>
      <origin rpy="0 0 0" xyz="0 0 0"/>
      <mass value="0.15"/>
      <inertia ixx="0.001859" ixy="-0.000376" ixz="0.000028" iyy="0.012756" iyz="0" izz="0.0024"/>
    </inertial>
  </link>
  <link name="finger_A_link_2">
    <!--
			NOTE: This link has an offset in the z-direction based on the models that were
			used to generate grap-it poses.  With the offset below the model appears visually
			correct, but it is suspect.
			-->
    <visual>
      <origin rpy="0 0 0" xyz="0.039 0 0.0075"/>
      <geometry>
        <mesh filename="meshes/robotiq-3f-gripper_articulated/visual/link_2.dae"/>
      </geometry>
      <material name="green"/>
    </visual>
    <collision>
      <origin rpy="0 0 0" xyz="0.039 0 0.0075"/>
      <geometry>
        <mesh filename="meshes/robotiq-3f-gripper_articulated/collision/link_2.STL"/>
      </geometry>
      <material name="yellow"/>
    </collision>
    <inertial>
      <origin rpy="0 0 0" xyz="0 0 0"/>
      <mass value="0.15"/>
      <inertia ixx="0.001859" ixy="-0.000376" ixz="0.000028" iyy="0.012756" iyz="0" izz="0.0024"/>
    </inertial>
  </link>
  <link name="finger_A_link_3">
    <visual>
      <origin rpy="0 0 0.47124" xyz="0 0 0"/>
      <geometry>
        <mesh filename="meshes/robotiq-3f-gripper_articulated/visual/link_3.dae"/>
      </geometry>
      <material name="red"/>
    </visual>
    <collision>
      <origin rpy="0 0 0.47124" xyz="0 0 0"/>
      <geometry>
        <mesh filename="meshes/robotiq-3f-gripper_articulated/collision/link_3.STL"/>
      </geometry>
      <material name="yellow"/>
    </collision>
    <inertial>
      <origin rpy="0 0 0" xyz="0 0 0"/>
      <mass value="0.05"/>
      <inertia ixx="0.001239" ixy="-0.000251" ixz="0.000019" iyy="0.00085" iyz="0" izz="0.001632"/>
    </inertial>
  </link>
  <joint name="finger_A_joint_1" type="revolute">
    <parent link="finger_A_link_0"/>
    <child link="finger_A_link_1"/>
    <axis xyz="0 0 1"/>
    <origin rpy="0 0 0" xyz="0.020 0 0"/>
    <limit effort="100" lower="0" upper="1.2217" velocity="100"/> <!-- 0 to 70 deg -->
  </joint>
  <joint name="finger_A_joint_2" type="revolute">
    <parent link="finger_A_link_1"/>
    <child link="finger_A_link_2"/>
    <axis xyz="0 0 1"/>
    <origin rpy="0 0 -0.47124" xyz="0.050 -.028 0"/>
    <limit effort="100" lower="0" upper="1.5708" velocity="100"/> <!-- 0 to 90 deg -->
  </joint>
  <joint name="finger_A_joint_3" type="revolute">
    <parent link="finger_A_link_2"/>
    <child link="finger_A_link_3"/>
    <axis xyz="0 0 1"/>
    <origin rpy="0 0 0" xyz="0.039 0 0"/>
    <limit effort="100" lower="-0.90757" upper="0.80285" velocity="100"/> <!-- -52 to 46 deg -->
  </joint>

  <link name="finger_B_link_0">
    <visual>
      <origin rpy="0 0 0" xyz="0.020 0 0"/>
      <geometry>
        <mesh filename="meshes/robotiq-3f-gripper_articulated/visual/link_0.dae"/>
      </geometry>
      <material name="green"/>
    </visual>
    <collision>
      <origin rpy="0 3.1416 -1.5708" xyz="-0.0455 0.0414 0.036"/>
      <geometry>
        <mesh filename="meshes/robotiq-3f-gripper_articulated/collision/link_0.STL"/>
      </geometry>
      <material name="yellow"/>
    </collision>
    <inertial>
      <origin rpy="0 0 0" xyz="0 0 0"/>
      <mass value="0.05"/>
      <inertia ixx="0.01" ixy="-0.00002" ixz="0.00001" iyy="0.0008" iyz="0" izz="0.001"/>
    </inertial>
  </link>
  <link name="finger_B_link_1">
    <visual>
      <origin rpy="0 0 -0.47124" xyz="0.050 -.028 0"/>
      <geometry>
        <mesh filename="meshes/robotiq-3f-gripper_articulated/visual/link_1.dae"/>
      </geometry>
      <material name="red"/>
    </visual>
    <collision>
      <origin rpy="0 0 -0.47124" xyz="0.050 -.028 0"/>
      <geometry>
        <mesh filename="meshes/robotiq-3f-gripper_articulated/collision/link_1.STL"/>
      </geometry>
      <material name="yellow"/>
    </collision>
    <inertial>
      <origin rpy="0 0 0" xyz="0 0 0"/>
      <mass value="0.15"/>
      <inertia ixx="0.001859" ixy="-0.000376" ixz="0.000028" iyy="0.012756" iyz="0" izz="0.0024"/>
    </inertial>
  </link>
  <link name="finger_B_link_2">
    <!--
			NOTE: This link has an offset in the z-direction based on the models that were
			used to generate grap-it poses.  With the offset below the model appears visually
			correct, but it is suspect.
			-->
    <visual>
      <origin rpy="0 0 0" xyz="0.039 0 0.0075"/>
      <geometry>
        <mesh filename="meshes/robotiq-3f-gripper_articulated/visual/link_2.dae"/>
      </geometry>
      <material name="green"/>
    </visual>
    <collision>
      <origin rpy="0 0 0" xyz="0.039 0 0.0075"/>
      <geometry>
        <mesh filename="meshes/robotiq-3f-gripper_articulated/collision/link_2.STL"/>
      </geometry>
      <material name="yellow"/>
    </collision>
    <inertial>
      <origin rpy="0 0 0" xyz="0 0 0"/>
      <mass value="0.15"/>
      <inertia ixx="0.001859" ixy="-0.000376" ixz="0.000028" iyy="0.012756" iyz="0" izz="0.0024"/>
    </inertial>
  </link>
  <link name="finger_B_link_3">
    <visual>
      <origin rpy="0 0 0.47124" xyz="0 0 0"/>
      <geometry>
        <mesh filename="meshes/robotiq-3f-gripper_articulated/visual/link_3.dae"/>
      </geometry>
      <material name="red"/>
    </visual>
    <collision>
      <origin rpy="0 0 0.47124" xyz="0 0 0"/>
      <geometry>
        <mesh filename="meshes/robotiq-3f-gripper_articulated/collision/link_3.STL"/>
      </geometry>
      <material name="yellow"/>
    </collision>
    <inertial>
      <origin rpy="0 0 0" xyz="0 0 0"/>
      <mass value="0.05"/>
      <inertia ixx="0.001239" ixy="-0.000251" ixz="0.000019" iyy="0.00085" iyz="0" izz="0.001632"/>
    </inertial>
  </link>
  <joint name="finger_B_joint_1" type="revolute">
    <parent link="finger_B_link_0"/>
    <child link="finger_B_link_1"/>
    <axis xyz="0 0 1"/>
    <origin rpy="0 0 0" xyz="0.020 0 0"/>
    <limit effort="100" lower="0" upper="1.2217" velocity="100"/> <!-- 0 to 70 deg -->
  </joint>
  <joint name="finger_B_joint_2" type="revolute">
    <parent link="finger_B_link_1"/>
    <child link="finger_B_link_2"/>
    <axis xyz="0 0 1"/>
    <origin rpy="0 0 -0.47124" xyz="0.050 -.028 0"/>
    <limit effort="100" lower="0" upper="1.5708" velocity="100"/> <!-- 0 to 90 deg -->
  </joint>
  <joint name="finger_B_joint_3" type="revolute">
    <parent link="finger_B_link_2"/>
    <child link="finger_B_link_3"/>
    <axis xyz="0 0 1"/>
    <origin rpy="0 0 0" xyz="0.039 0 0"/>
    <limit effort="100" lower="-0.90757" upper="0.80285" velocity="100"/> <!-- -52 to 46 deg -->
  </joint>
  
  <link name="finger_C_link_0">
    <visual>
      <origin rpy="0 0 0" xyz="0.020 0 0"/>
      <geometry>
        <mesh filename="meshes/robotiq-3f-gripper_articulated/visual/link_0.dae"/>
      </geometry>
      <material name="green"/>
    </visual>
    <collision>
      <origin rpy="0 3.1416 -1.5708" xyz="-0.0455 0.0414 0.036"/>
      <geometry>
        <mesh filename="meshes/robotiq-3f-gripper_articulated/collision/link_0.STL"/>
      </geometry>
      <material name="yellow"/>
    </collision>
    <inertial>
      <origin rpy="0 0 0" xyz="0 0 0"/>
      <mass value="0.05"/>
      <inertia ixx="0.01" ixy="-0.00002" ixz="0.00001" iyy="0.0008" iyz="0" izz="0.001"/>
    </inertial>
  </link>
  <link name="finger_C_link_1">
    <visual>
      <origin rpy="0 0 -0.47124" xyz="0.050 -.028 0"/>
      <geometry>
        <mesh filename="meshes/robotiq-3f-gripper_articulated/visual/link_1.dae"/>
      </geometry>
      <material name="red"/>
    </visual>
    <collision>
      <origin rpy="0 0 -0.47124" xyz="0.050 -.028 0"/>
      <geometry>
        <mesh filename="meshes/robotiq-3f-gripper_articulated/collision/link_1.STL"/>
      </geometry>
      <material name="yellow"/>
    </collision>
    <inertial>
      <origin rpy="0 0 0" xyz="0 0 0"/>
      <mass value="0.15"/>
      <inertia ixx="0.001859" ixy="-0.000376" ixz="0.000028" iyy="0.012756" iyz="0" izz="0.0024"/>
    </inertial>
  </link>
  <link name="finger_C_link_2">
    <!--
			NOTE: This link has an offset in the z-direction based on the models that were
			used to generate grap-it poses.  With the offset below the model appears visually
			correct, but it is suspect.
			-->
    <visual>
      <origin rpy="0 0 0" xyz="0.039 0 0.0075"/>
      <geometry>
        <mesh filename="meshes/robotiq-3f-gripper_articulated/visual/link_2.dae"/>
      </geometry>
      <material name="green"/>
    </visual>
    <collision>
      <origin rpy="0 0 0" xyz="0.039 0 0.0075"/>
      <geometry>
        <mesh filename="meshes/robotiq-3f-gripper_articulated/collision/link_2.STL"/>
      </geometry>
      <material name="yellow"/>
    </collision>
    <inertial>
      <origin rpy="0 0 0" xyz="0 0 0"/>
      <mass value="0.15"/>
      <inertia ixx="0.001859" ixy="-0.000376" ixz="0.000028" iyy="0.012756" iyz="0" izz="0.0024"/>
    </inertial>
  </link>
  <link name="finger_C_link_3">
    <visual>
      <origin rpy="0 0 0.47124" xyz="0 0 0"/>
      <geometry>
        <mesh filename="meshes/robotiq-3f-gripper_articulated/visual/link_3.dae"/>
      </geometry>
      <material name="red"/>
    </visual>
    <collision>
      <origin rpy="0 0 0.47124" xyz="0 0 0"/>
      <geometry>
        <mesh filename="meshes/robotiq-3f-gripper_articulated/collision/link_3.STL"/>
      </geometry>
      <material name="yellow"/>
    </collision>
    <inertial>
      <origin rpy="0 0 0" xyz="0 0 0"/>
      <mass value="0.05"/>
      <inertia ixx="0.001239" ixy="-0.000251" ixz="0.000019" iyy="0.00085" iyz="0" izz="0.001632"/>
    </inertial>
  </link>
  <joint name="finger_C_joint_1" type="revolute">
    <parent link="finger_C_link_0"/>
    <child link="finger_C_link_1"/>
    <axis xyz="0 0 1"/>
    <origin rpy="0 0 0" xyz="0.020 0 0"/>
    <limit effort="100" lower="0" upper="1.2217" velocity="100"/> <!-- 0 to 70 deg -->
  </joint>
  <joint name="finger_C_joint_2" type="revolute">
    <parent link="finger_C_link_1"/>
    <child link="finger_C_link_2"/>
    <axis xyz="0 0 1"/>
    <origin rpy="0 0 -0.47124" xyz="0.050 -.028 0"/>
    <limit effort="100" lower="0" upper="1.5708" velocity="100"/> <!-- 0 to 90 deg -->
  </joint>
  <joint name="finger_C_joint_3" type="revolute">
    <parent link="finger_C_link_2"/>
    <child link="finger_C_link_3"/>
    <axis xyz="0 0 1"/>
    <origin rpy="0 0 0" xyz="0.039 0 0"/>
    <limit effort="100" lower="-0.90757" upper="0.80285" velocity="100"/> <!-- -52 to 46 deg -->
  </joint>

  <link name="palm">
    <visual>
      <geometry>
        <mesh filename="meshes/robotiq-3f-gripper_articulated/visual/palm.dae"/>
      </geometry>
      <material name="yellow"/>
    </visual>
    <collision>
      <geometry>
        <mesh filename="meshes/robotiq-3f-gripper_articulated/collision/palm.STL"/>
      </geometry>
      <material name="yellow"/>
    </collision>
    <inertial>
      <origin rpy="0 0 0" xyz="0 0 0"/>
      <mass value="1.3"/>
      <inertia ixx="0.006012" ixy="0.000079" ixz="-0.00024" iyy="0.012892" iyz="0" izz="0.002435"/>
    </inertial>
  </link>

  <joint name="palm_finger_A_joint" type="fixed">
    <parent link="palm"/>
    <child link="finger_A_link_0"/>
    <axis xyz="0 0 1"/>
    <origin rpy="0 0 1.5708" xyz="0.0455 0.0214 0"/>
  </joint>
  <joint name="palm_finger_B_joint" type="revolute">
    <parent link="palm"/>
    <child link="finger_B_link_0"/>
    <axis xyz="0 1 0"/>
    <origin rpy="0 3.1416 -1.5708" xyz="-0.0455 0.0214 -0.036"/>
    <limit effort="100" lower="-0.27925" upper="0.17453" velocity="100"/> <!-- -16 to 10 deg -->
  </joint>
  <joint name="palm_finger_C_joint" type="revolute">
    <parent link="palm"/>
    <child link="finger_C_link_0"/>
    <axis xyz="0 1 0"/>
    <origin rpy="0 3.1416 -1.5708" xyz="-0.0455 0.0214 0.036"/>
    <limit effort="100" lower="-0.17453" upper="0.27925" velocity="100"/> <!-- -10 to 16 deg -->
  </joint>

  <joint name="ee_fixed_joint" type="fixed">
    <parent link="wrist_3_link"/>
    <child link="palm"/>
    <!-- <origin rpy="0.0 0.0 0.0" xyz="0.0 0.0922 0.0"/> -->
    <origin rpy="0 0 0" xyz="0 0.147 0"/>
  </joint>


  <transmission name="shoulder_pan_trans">
    <type>transmission_interface/SimpleTransmission</type>
    <joint name="shoulder_pan_joint"/>
    <actuator name="shoulder_pan_motor">
      <hardwareInterface>EffortJointInterface</hardwareInterface>
      <mechanicalReduction>1</mechanicalReduction>
    </actuator>
  </transmission>
  <transmission name="shoulder_lift_trans">
    <type>transmission_interface/SimpleTransmission</type>
    <joint name="shoulder_lift_joint"/>
    <actuator name="shoulder_lift_motor">
      <hardwareInterface>EffortJointInterface</hardwareInterface>
      <mechanicalReduction>1</mechanicalReduction>
    </actuator>
  </transmission>
  <transmission name="elbow_trans">
    <type>transmission_interface/SimpleTransmission</type>
    <joint name="elbow_joint"/>
    <actuator name="elbow_motor">
      <hardwareInterface>EffortJointInterface</hardwareInterface>
      <mechanicalReduction>1</mechanicalReduction>
    </actuator>
  </transmission>
  <transmission name="wrist_1_trans">
    <type>transmission_interface/SimpleTransmission</type>
    <joint name="wrist_1_joint"/>
    <actuator name="wrist_1_motor">
      <hardwareInterface>EffortJointInterface</hardwareInterface>
      <mechanicalReduction>1</mechanicalReduction>
    </actuator>
  </transmission>
  <transmission name="wrist_2_trans">
    <type>transmission_interface/SimpleTransmission</type>
    <joint name="wrist_2_joint"/>
    <actuator name="wrist_2_motor">
      <hardwareInterface>EffortJointInterface</hardwareInterface>
      <mechanicalReduction>1</mechanicalReduction>
    </actuator>
  </transmission>
  <transmission name="wrist_3_trans">
    <type>transmission_interface/SimpleTransmission</type>
    <joint name="wrist_3_joint"/>
    <actuator name="wrist_3_motor">
      <hardwareInterface>EffortJointInterface</hardwareInterface>
      <mechanicalReduction>1</mechanicalReduction>
    </actuator>
  </transmission>
  <link name="world"/>
  <joint name="world_joint" type="fixed">
    <parent link="world"/>
    <child link="base_link"/>
    <origin rpy="0.0 0.0 0.0" xyz="0.0 0.0 0.0"/>
  </joint>
</robot>